<robot name="biped">
    <link name="base">
      <inertial>
        <origin xyz="0.0 0.0 0.0" rpy="0.0 0.0 0.0"/>
        <mass value="0.5"/>
        <inertia ixx="0.01" ixy="0.0" ixz="0.0" iyy="0.01" iyz="0.0" izz="0.006"/>
      </inertial>
	    <visual>
	      <geometry>
	        <box size="0.30 0.30 0.30"/>
	      </geometry>
	      <material name="gray">
	        <color rgba="0.3 0.3 0.3 1.0"/>
	      </material>
	    </visual>        
    </link>

    <!-- LEFT LEG -->
    <link name="L_hipassembly">
	    <visual>
	      <origin rpy="0.0 0.0 0.0" xyz="0.0 0.0 0.0"/>
	      <geometry>
	        <mesh filename="../meshes/leg/hipassembly.stl" scale="1 1 1"/>
	      </geometry>
	      <material name="white"/>
	    </visual>  
    <inertial>
      <origin rpy="0 0 0" xyz="-0.022191 0.015144 -1.5e-05"/>
      <mass value="1.993"/>
      <inertia ixx="0.002903894" ixy="-7.185e-05" ixz="-1.262e-06" iyy="0.004907517" iyz="-1.75e-06" izz="0.005586944"/>
    </inertial>      
    </link>
    <link name="L_upperleg">
	    <visual>
	      <origin rpy="0.0 0.0 0.0" xyz="0.0 0.0 0.0"/>
	      <geometry>
	        <mesh filename="../meshes/leg/upperleg.stl" scale="1 1 1"/>
	      </geometry>
	      <material name="blue"/>
	    </visual>
    <inertial>
      <origin rpy="0 0 0" xyz="-0.022191 0.015144 -1.5e-05"/>
      <mass value="1.993"/>
      <inertia ixx="0.002903894" ixy="-7.185e-05" ixz="-1.262e-06" iyy="0.004907517" iyz="-1.75e-06" izz="0.005586944"/>
    </inertial>

    </link>
    <link name="L_lowerleg">
	    <visual>
	      <geometry>
	        <mesh filename="../meshes/leg/lowerleg.stl" scale="1 1 1"/>
	      </geometry>
	      <material name="blue"/>
	    </visual>    
    <inertial>
      <origin rpy="0 0 0" xyz="-0.022191 0.015144 -1.5e-05"/>
      <mass value="1.993"/>
      <inertia ixx="0.002903894" ixy="-7.185e-05" ixz="-1.262e-06" iyy="0.004907517" iyz="-1.75e-06" izz="0.005586944"/>
    </inertial>    
    </link>
    
    <joint name="L_haa_joint" type="revolute">
        <origin xyz="0.00000 0.1 -0.15000" rpy="2.0344439357957036 1.5707962290814481 -1.1071487177940917"/>
        <parent link="base"/>
        <child  link="L_hipassembly"/>
        <limit effort="200" lower="-1.6" upper="1.6" velocity="1.0"/>
        <axis xyz="0 0 1"/>
    </joint>
    <joint name="L_hfe_joint" type="revolute">
        <origin xyz="0.08000 0.00000 0.00000" rpy="1.5707963705062866 -0.0 0.0"/>
        <parent link="L_hipassembly"/>
        <child  link="L_upperleg"/>
        <limit effort="200" lower="-1.6" upper="1.6" velocity="1.0"/>
        <axis xyz="0 0 1"/>
    </joint>
    <joint name="L_kfe_joint" type="revolute">
        <origin xyz="0.35000 0.00000 0.00000" rpy="0.0 0.0 0.0"/>
        <parent link="L_upperleg"/>
        <child  link="L_lowerleg"/>
        <limit effort="200" lower="-1.6" upper="1.6" velocity="1.0"/>
        <axis xyz="0 0 1"/>
    </joint>
    
    
    
    <!-- RIGHT LEG -->
    <link name="R_hipassembly">
      <visual>
        <origin rpy="0.0 0.0 0.0" xyz="0.0 0.0 0.0"/>
        <geometry>
          <mesh filename="../meshes/leg/hipassembly.stl" scale="1 1 1"/>
        </geometry>
        <material name="white"/>
      </visual>   
    <inertial>
      <origin rpy="0 0 0" xyz="-0.022191 0.015144 -1.5e-05"/>
      <mass value="1.993"/>
      <inertia ixx="0.002903894" ixy="-7.185e-05" ixz="-1.262e-06" iyy="0.004907517" iyz="-1.75e-06" izz="0.005586944"/>
    </inertial>

    </link>
    <link name="R_upperleg">
      <visual>
        <origin rpy="0.0 0.0 0.0" xyz="0.0 0.0 0.0"/>
        <geometry>
          <mesh filename="../meshes/leg/upperleg.stl" scale="1 1 1"/>
        </geometry>
        <material name="blue"/>
      </visual>
    <inertial>
      <origin rpy="0 0 0" xyz="-0.022191 0.015144 -1.5e-05"/>
      <mass value="1.993"/>
      <inertia ixx="0.002903894" ixy="-7.185e-05" ixz="-1.262e-06" iyy="0.004907517" iyz="-1.75e-06" izz="0.005586944"/>
    </inertial>
    </link>
    <link name="R_lowerleg">
      <visual>
        <geometry>
          <mesh filename="../meshes/leg/lowerleg.stl" scale="1 1 1"/>
        </geometry>
        <material name="blue"/>
      </visual>  
  
    </link>
    
    <joint name="R_haa_joint" type="revolute">
        <origin xyz="0.00000 -0.1 -0.15000" rpy="2.0344439357957036 1.5707962290814481 -1.1071487177940917"/>
        <parent link="base"/>
        <child  link="R_hipassembly"/>
        <limit effort="200" lower="-1.6" upper="1.6" velocity="1.0"/>
        <axis xyz="0 0 1"/>
    </joint>
    <joint name="R_hfe_joint" type="revolute">
        <origin xyz="0.08000 0.00000 0.00000" rpy="1.5707963705062866 -0.0 0.0"/>
        <parent link="R_hipassembly"/>
        <child  link="R_upperleg"/>
        <limit effort="200" lower="-1.6" upper="1.6" velocity="1.0"/>
        <axis xyz="0 0 1"/>
    </joint>
    <joint name="R_kfe_joint" type="revolute">
        <origin xyz="0.35000 0.00000 0.00000" rpy="0.0 0.0 0.0"/>
        <parent link="R_upperleg"/>
        <child  link="R_lowerleg"/>
        <limit effort="200" lower="-1.6" upper="1.6" velocity="1.0"/>
        <axis xyz="0 0 1"/>
    </joint>
    
    
</robot>

