<?xml version="1.0" encoding="utf-8"?>
<!-- =================================================================================== -->
<!-- |    This document was autogenerated by xacro from a600_description.xacro         | -->
<!-- |    EDITING THIS FILE BY HAND IS NOT RECOMMENDED                                 | -->
<!-- =================================================================================== -->
<robot name="AR-600">
  <!-- Color -->
  <material name="black">
    <color rgba="0.0 0.0 0.0 1.0"/>
  </material>
  <material name="blue">
    <color rgba="0.0 0.0 0.8 1.0"/>
  </material>
  <material name="green">
    <color rgba="0.0 0.8 0.0 1.0"/>
  </material>
  <material name="grey">
    <color rgba="0.2 0.2 0.2 1.0"/>
  </material>
  <material name="orange">
    <color rgba="1.0 0.423529411765 0.0392156862745 1.0"/>
  </material>
  <material name="brown">
    <color rgba="0.870588235294 0.811764705882 0.764705882353 1.0"/>
  </material>
  <material name="red">
    <color rgba="0.8 0.0 0.0 1.0"/>
  </material>
  <material name="white">
    <color rgba="1.0 1.0 1.0 1.0"/>
  </material>
  <!-- Gazebo plugin -->

  <!-- <link name="dummy">
   </link>
  <joint name="dummy_joint" type="fixed">
     <parent link="dummy"/>
     <child link="body"/>
   </joint> -->
  <link name="base_link">
    <inertial>
      <mass value="28.386"/>
      <origin rpy="0 0 0" xyz="-0.0014901 0.13851 0.00071357"/>
      <inertia ixx="0.073017" ixy="-3.603e-05" ixz="5.7649e-06" iyy="0.085864" iyz="0.0040898" izz="0.10252"/>
    </inertial>
    <collision>
      <origin rpy="0 0 0" xyz="0 0 0"/>
      <geometry>
        <mesh filename="../meshes/base_link.STL"/>
      </geometry>
    </collision>
    <visual>
      <origin rpy="0 0 0" xyz="0 0 0"/>
      <geometry>
        <mesh filename="../meshes/base_link.STL"/>
      </geometry>
      <material name="orange"/>
    </visual>
  </link>
  <link name="R_HipR">
    <inertial>
      <mass value="2.3558"/>
      <origin rpy="0 0 0" xyz="0.00071161 -0.027458 -0.023065"/>
      <inertia ixx="0.0032395" ixy="1.8675e-05" ixz="-4.6222e-05" iyy="0.0032177" iyz="7.5574e-06" izz="0.0025538"/>
    </inertial>
    <collision>
      <origin rpy="0 0 0" xyz="0 0 0"/>
      <geometry>
        <mesh filename="../meshes/R_HipR.STL"/>
      </geometry>
    </collision>
    <visual>
      <origin rpy="0 0 0" xyz="0 0 0"/>
      <geometry>
        <mesh filename="../meshes/R_HipR.STL"/>
      </geometry>
      <material name="orange"/>
    </visual>
  </link>
  <joint name="R_HipR" type="revolute">
    <axis xyz="0 1 0"/>
    <limit effort="1000" lower="-1.04719755" upper="1.04719755" velocity="0.5"/>
    <origin rpy="1.5708 0 0" xyz="-0.088 -0.027645 0"/>
    <parent link="base_link"/>
    <child link="R_HipR"/>
  </joint>
  <!-- transmission -->
  <transmission name="trans_R_HipR">
    <type>transmission_interface/SimpleTransmission</type>
    <joint name="R_HipR">
      <hardwareInterface>hardware_interface/EffortJointInterface</hardwareInterface>
    </joint>
    <actuator name="motor_R_HipR">
      <hardwareInterface>hardware_interface/EffortJointInterface</hardwareInterface>
      <mechanicalReduction>1</mechanicalReduction>
    </actuator>
  </transmission>
  <link name="R_HipS">
    <inertial>
      <mass value="6.15"/>
      <origin rpy="0 0 0" xyz="0.0032793 0.00011106 0.025957"/>
      <inertia ixx="0.0051093" ixy="1.2709e-05" ixz="7.1765e-06" iyy="0.0048779" iyz="-5.4798e-06" izz="0.0062721"/>
    </inertial>
    <collision>
      <origin rpy="0 0 0" xyz="0 0 0"/>
      <geometry>
        <mesh filename="../meshes/R_HipS.STL"/>
      </geometry>
    </collision>
    <visual>
      <origin rpy="0 0 0" xyz="0 0 0"/>
      <geometry>
        <mesh filename="../meshes/R_HipS.STL"/>
      </geometry>
      <material name="orange"/>
    </visual>
  </link>
  <joint name="R_HipS" type="revolute">
    <axis xyz="0 0 1"/>
    <limit effort="1000" lower="-1.04719755" upper="1.04719755" velocity="0.5"/>
    <origin rpy="3.1416 0 3.1416" xyz="0 -0.102 0"/>
    <parent link="R_HipR"/>
    <child link="R_HipS"/>
  </joint>
  <!-- transmission -->
  <transmission name="trans_R_HipS">
    <type>transmission_interface/SimpleTransmission</type>
    <joint name="R_HipS">
      <hardwareInterface>hardware_interface/EffortJointInterface</hardwareInterface>
    </joint>
    <actuator name="motor_R_HipS">
      <hardwareInterface>hardware_interface/EffortJointInterface</hardwareInterface>
      <mechanicalReduction>1</mechanicalReduction>
    </actuator>
  </transmission>
  <link name="R_Knee_Upper">
    <inertial>
      <mass value="16.331"/>
      <origin rpy="0 0 0" xyz="0.018772 -0.22402 -0.0063916"/>
      <inertia ixx="0.048034" ixy="2.0407e-07" ixz="-6.8084e-05" iyy="0.015142" iyz="-0.00213" izz="0.039371"/>
    </inertial>
    <collision>
      <origin rpy="0 0 0" xyz="0 0 0"/>
      <geometry>
        <mesh filename="../meshes/R_Knee_Upper.STL"/>
      </geometry>
    </collision>
    <visual>
      <origin rpy="0 0 0" xyz="0 0 0"/>
      <geometry>
        <mesh filename="../meshes/R_Knee_Upper.STL"/>
      </geometry>
      <material name="orange"/>
    </visual>
  </link>
  <joint name="R_Knee_Upper" type="revolute">
    <axis xyz="1 0 0"/>
    <limit effort="1000" lower="-1.04719755" upper="1.04719755" velocity="0.5"/>
    <origin rpy="0 0 0" xyz="0 0 0"/>
    <parent link="R_HipS"/>
    <child link="R_Knee_Upper"/>
  </joint>
  <!-- transmission -->
  <transmission name="trans_R_Knee_Upper">
    <type>transmission_interface/SimpleTransmission</type>
    <joint name="R_Knee_Upper">
      <hardwareInterface>hardware_interface/EffortJointInterface</hardwareInterface>
    </joint>
    <actuator name="motor_R_Knee_Upper">
      <hardwareInterface>hardware_interface/EffortJointInterface</hardwareInterface>
      <mechanicalReduction>1</mechanicalReduction>
    </actuator>
  </transmission>
  <link name="R_Knee_Lower">
    <inertial>
      <mass value="10.03"/>
      <origin rpy="0 0 0" xyz="-0.011938 -0.17383 0.0029031"/>
      <inertia ixx="0.020389" ixy="3.5365e-08" ixz="-9.649e-07" iyy="0.0072632" iyz="8.7687e-05" izz="0.015199"/>
    </inertial>
    <collision>
      <origin rpy="0 0 0" xyz="0 0 0"/>
      <geometry>
        <mesh filename="../meshes/R_Knee_Lower.STL"/>
      </geometry>
    </collision>
    <visual>
      <origin rpy="0 0 0" xyz="0 0 0"/>
      <geometry>
        <mesh filename="../meshes/R_Knee_Lower.STL"/>
      </geometry>
      <material name="orange"/>
    </visual>
  </link>
  <joint name="R_Knee_Lower" type="revolute">
    <axis xyz="1 0 0"/>
    <limit effort="1000" lower="-1.04719755" upper="1.04719755" velocity="0.5"/>
    <origin rpy="3.1416 0 3.1416" xyz="0 -0.28 0"/>
    <parent link="R_Knee_Upper"/>
    <child link="R_Knee_Lower"/>
  </joint>
  <!-- transmission -->
  <transmission name="trans_R_Knee_Lower">
    <type>transmission_interface/SimpleTransmission</type>
    <joint name="R_Knee_Lower">
      <hardwareInterface>hardware_interface/EffortJointInterface</hardwareInterface>
    </joint>
    <actuator name="motor_R_Knee_Lower">
      <hardwareInterface>hardware_interface/EffortJointInterface</hardwareInterface>
      <mechanicalReduction>1</mechanicalReduction>
    </actuator>
  </transmission>
  <link name="R_FootR">
    <inertial>
      <mass value="1.1565"/>
      <origin rpy="0 0 0" xyz="-0.00069157 0.029306 0.012871"/>
      <inertia ixx="0.00063348" ixy="-6.7285e-07" ixz="-4.078e-08" iyy="0.00057147" iyz="-3.7116e-06" izz="0.0003019"/>
    </inertial>
    <collision>
      <origin rpy="0 0 0" xyz="0 0 0"/>
      <geometry>
        <mesh filename="../meshes/R_FootR.STL"/>
      </geometry>
    </collision>
    <visual>
      <origin rpy="0 0 0" xyz="0 0 0"/>
      <geometry>
        <mesh filename="../meshes/R_FootR.STL"/>
      </geometry>
      <material name="orange"/>
    </visual>
  </link>
  <joint name="R_FootR" type="revolute">
    <axis xyz="0.99994 -0.010843 0"/>
    <limit effort="1000" lower="-1.04719755" upper="1.04719755" velocity="0.5"/>
    <origin rpy="3.1053 -0.00039391 -0.010836" xyz="0 -0.27682 0.010063"/>
    <parent link="R_Knee_Lower"/>
    <child link="R_FootR"/>
  </joint>
  <!-- transmission -->
  <transmission name="trans_R_FootR">
    <type>transmission_interface/SimpleTransmission</type>
    <joint name="R_FootR">
      <hardwareInterface>hardware_interface/EffortJointInterface</hardwareInterface>
    </joint>
    <actuator name="motor_R_FootR">
      <hardwareInterface>hardware_interface/EffortJointInterface</hardwareInterface>
      <mechanicalReduction>1</mechanicalReduction>
    </actuator>
  </transmission>
  <link name="R_FootS">
    <inertial>
      <mass value="11.269"/>
      <origin rpy="0 0 0" xyz="-6.0221E-05 0.080294 -0.056863"/>
      <inertia ixx="0.02985" ixy="-1.1479e-05" ixz="7.8243e-06" iyy="0.03455" iyz="0.00043103" izz="0.0088348"/>
    </inertial>
    <collision>
      <origin rpy="0 0 0" xyz="0 0 0"/>
      <geometry>
        <mesh filename="../meshes/R_FootS.STL"/>
      </geometry>
    </collision>
    <visual>
      <origin rpy="0 0 0" xyz="0 0 0"/>
      <geometry>
        <mesh filename="../meshes/R_FootS.STL"/>
      </geometry>
      <material name="orange"/>
    </visual>
  </link>
  <joint name="R_FootS" type="revolute">
    <axis xyz="0 0 1"/>
    <limit effort="1000" lower="-1.04719755" upper="1.04719755" velocity="0.5"/>
    <origin rpy="0 0 0" xyz="-0.00032467 0.030005 0"/>
    <parent link="R_FootR"/>
    <child link="R_FootS"/>
  </joint>
  <!-- transmission -->
  <transmission name="trans_R_FootS">
    <type>transmission_interface/SimpleTransmission</type>
    <joint name="R_FootS">
      <hardwareInterface>hardware_interface/EffortJointInterface</hardwareInterface>
    </joint>
    <actuator name="motor_R_FootS">
      <hardwareInterface>hardware_interface/EffortJointInterface</hardwareInterface>
      <mechanicalReduction>1</mechanicalReduction>
    </actuator>
  </transmission>
  <link name="L_HipR">
    <inertial>
      <mass value="2.388"/>
      <origin rpy="0 0 0" xyz="-0.00070201 -0.027248 -0.022799"/>
      <inertia ixx="0.00324" ixy="-1.8675e-05" ixz="4.6222e-05" iyy="0.003218" iyz="7.5574e-06" izz="0.0025543"/>
    </inertial>
    <collision>
      <origin rpy="0 0 0" xyz="0 0 0"/>
      <geometry>
        <mesh filename="../meshes/L_HipR.STL"/>
      </geometry>
    </collision>
    <visual>
      <origin rpy="0 0 0" xyz="0 0 0"/>
      <geometry>
        <mesh filename="../meshes/L_HipR.STL"/>
      </geometry>
      <material name="orange"/>
    </visual>
  </link>
  <joint name="L_HipR" type="revolute">
    <axis xyz="0 1 0"/>
    <limit effort="1000" lower="-1.04719755" upper="1.04719755" velocity="0.5"/>
    <origin rpy="1.5708 0 0" xyz="0.088 -0.027645 0"/>
    <parent link="base_link"/>
    <child link="L_HipR"/>
  </joint>
  <!-- transmission -->
  <transmission name="trans_L_HipR">
    <type>transmission_interface/SimpleTransmission</type>
    <joint name="L_HipR">
      <hardwareInterface>hardware_interface/EffortJointInterface</hardwareInterface>
    </joint>
    <actuator name="motor_L_HipR">
      <hardwareInterface>hardware_interface/EffortJointInterface</hardwareInterface>
      <mechanicalReduction>1</mechanicalReduction>
    </actuator>
  </transmission>
  <link name="L_HipS">
    <inertial>
      <mass value="6.15"/>
      <origin rpy="0 0 0" xyz="0.0033351 0.00011632 -0.025364"/>
      <inertia ixx="0.005105" ixy="1.2895e-05" ixz="1.554e-07" iyy="0.0048687" iyz="1.0129e-05" izz="0.006262"/>
    </inertial>
    <collision>
      <origin rpy="0 0 0" xyz="0 0 0"/>
      <geometry>
        <mesh filename="../meshes/L_HipS.STL"/>
      </geometry>
    </collision>
    <visual>
      <origin rpy="0 0 0" xyz="0 0 0"/>
      <geometry>
        <mesh filename="../meshes/L_HipS.STL"/>
      </geometry>
      <material name="orange"/>
    </visual>
  </link>
  <joint name="L_HipS" type="revolute">
    <axis xyz="0 0 1"/>
    <limit effort="1000" lower="-1.04719755" upper="1.04719755" velocity="0.5"/>
    <origin rpy="0 0 0" xyz="0 -0.102 0"/>
    <parent link="L_HipR"/>
    <child link="L_HipS"/>
  </joint>
  <!-- transmission -->
  <transmission name="trans_L_HipS">
    <type>transmission_interface/SimpleTransmission</type>
    <joint name="L_HipS">
      <hardwareInterface>hardware_interface/EffortJointInterface</hardwareInterface>
    </joint>
    <actuator name="motor_L_HipS">
      <hardwareInterface>hardware_interface/EffortJointInterface</hardwareInterface>
      <mechanicalReduction>1</mechanicalReduction>
    </actuator>
  </transmission>
  <link name="L_Knee_upper">
    <inertial>
      <mass value="16.528"/>
      <origin rpy="0 0 0" xyz="0.018739 -0.22354 0.0087895"/>
      <inertia ixx="0.048222" ixy="4.2459e-06" ixz="6.2369e-05" iyy="0.015119" iyz="0.002184" izz="0.039943"/>
    </inertial>
    <collision>
      <origin rpy="0 0 0" xyz="0 0 0"/>
      <geometry>
        <mesh filename="../meshes/L_Knee_upper.STL"/>
      </geometry>
    </collision>
    <visual>
      <origin rpy="0 0 0" xyz="0 0 0"/>
      <geometry>
        <mesh filename="../meshes/L_Knee_upper.STL"/>
      </geometry>
      <material name="orange"/>
    </visual>
  </link>
  <joint name="L_Knee_upper" type="revolute">
    <axis xyz="1 0 0"/>
    <limit effort="1000" lower="-1.04719755" upper="1.04719755" velocity="0.5"/>
    <origin rpy="0 0 0" xyz="0 0 0"/>
    <parent link="L_HipS"/>
    <child link="L_Knee_upper"/>
  </joint>
  <!-- transmission -->
  <transmission name="trans_L_Knee_upper">
    <type>transmission_interface/SimpleTransmission</type>
    <joint name="L_Knee_upper">
      <hardwareInterface>hardware_interface/EffortJointInterface</hardwareInterface>
    </joint>
    <actuator name="motor_L_Knee_upper">
      <hardwareInterface>hardware_interface/EffortJointInterface</hardwareInterface>
      <mechanicalReduction>1</mechanicalReduction>
    </actuator>
  </transmission>
  <link name="L_Knee_Lower">
    <inertial>
      <mass value="10.498"/>
      <origin rpy="0 0 0" xyz="0.011812 -0.16731 -0.0034716"/>
      <inertia ixx="0.021077" ixy="-1.0082e-06" ixz="-1.8986e-06" iyy="0.007636" iyz="-0.00016695" izz="0.01553"/>
    </inertial>
    <collision>
      <origin rpy="0 0 0" xyz="0 0 0"/>
      <geometry>
        <mesh filename="../meshes/L_Knee_Lower.STL"/>
      </geometry>
    </collision>
    <visual>
      <origin rpy="0 0 0" xyz="0 0 0"/>
      <geometry>
        <mesh filename="../meshes/L_Knee_Lower.STL"/>
      </geometry>
      <material name="orange"/>
    </visual>
  </link>
  <joint name="L_Knee_Lower" type="revolute">
    <axis xyz="1 0 0"/>
    <limit effort="1000" lower="-1.04719755" upper="1.04719755" velocity="0.5"/>
    <origin rpy="-0.036336 0 0" xyz="0 -0.28 0"/>
    <parent link="L_Knee_upper"/>
    <child link="L_Knee_Lower"/>
  </joint>
  <!-- transmission -->
  <transmission name="trans_L_Knee_Lower">
    <type>transmission_interface/SimpleTransmission</type>
    <joint name="L_Knee_Lower">
      <hardwareInterface>hardware_interface/EffortJointInterface</hardwareInterface>
    </joint>
    <actuator name="motor_L_Knee_Lower">
      <hardwareInterface>hardware_interface/EffortJointInterface</hardwareInterface>
      <mechanicalReduction>1</mechanicalReduction>
    </actuator>
  </transmission>
  <link name="L_FootR">
    <inertial>
      <mass value="1.1565"/>
      <origin rpy="0 0 0" xyz="0.00060836 0.029292 0.012871"/>
      <inertia ixx="0.00063348" ixy="-6.7285e-07" ixz="-4.078e-08" iyy="0.00057147" iyz="-3.7116e-06" izz="0.0003019"/>
    </inertial>
    <collision>
      <origin rpy="0 0 0" xyz="0 0 0"/>
      <geometry>
        <mesh filename="../meshes/L_FootR.STL"/>
      </geometry>
    </collision>
    <visual>
      <origin rpy="0 0 0" xyz="0 0 0"/>
      <geometry>
        <mesh filename="../meshes/L_FootR.STL"/>
      </geometry>
      <material name="orange"/>
    </visual>
  </link>
  <joint name="L_FootR" type="revolute">
    <axis xyz="0.99994 -0.010843 0"/>
    <limit effort="1000" lower="-1.04719755" upper="1.04719755" velocity="0.5"/>
    <origin rpy="3.1416 0 -0.010843" xyz="0 -0.277 0"/>
    <parent link="L_Knee_Lower"/>
    <child link="L_FootR"/>
  </joint>
  <!-- transmission -->
  <transmission name="trans_L_FootR">
    <type>transmission_interface/SimpleTransmission</type>
    <joint name="L_FootR">
      <hardwareInterface>hardware_interface/EffortJointInterface</hardwareInterface>
    </joint>
    <actuator name="motor_L_FootR">
      <hardwareInterface>hardware_interface/EffortJointInterface</hardwareInterface>
      <mechanicalReduction>1</mechanicalReduction>
    </actuator>
  </transmission>
  <link name="L_FootS">
    <inertial>
      <mass value="11.269"/>
      <origin rpy="0 0 0" xyz="-6.0221E-05 0.080294 -0.056863"/>
      <inertia ixx="0.02985" ixy="-1.1479e-05" ixz="7.8243e-06" iyy="0.03455" iyz="0.00043103" izz="0.0088348"/>
    </inertial>
    <collision>
      <origin rpy="0 0 0" xyz="0 0 0"/>
      <geometry>
        <mesh filename="../meshes/L_FootS.STL"/>
      </geometry>
    </collision>
    <visual>
      <origin rpy="0 0 0" xyz="0 0 0"/>
      <geometry>
        <mesh filename="../meshes/L_FootS.STL"/>
      </geometry>
      <material name="orange"/>
    </visual>
  </link>
  <joint name="L_FootS" type="revolute">
    <axis xyz="0 0 1"/>
    <limit effort="1000" lower="-1.04719755" upper="1.04719755" velocity="0.5"/>
    <origin rpy="0 0 0" xyz="0.00097526 0.029991 0"/>
    <parent link="L_FootR"/>
    <child link="L_FootS"/>
  </joint>
  <!-- transmission -->
  <transmission name="trans_L_FootS">
    <type>transmission_interface/SimpleTransmission</type>
    <joint name="L_FootS">
      <hardwareInterface>hardware_interface/EffortJointInterface</hardwareInterface>
    </joint>
    <actuator name="motor_L_FootS">
      <hardwareInterface>hardware_interface/EffortJointInterface</hardwareInterface>
      <mechanicalReduction>1</mechanicalReduction>
    </actuator>
  </transmission>
</robot>
