<?xml version="1.0" encoding="utf-8"?>
<!-- =================================================================================== -->
<!-- |    This document was autogenerated by xacro from ../xacro/robot.xacro           | -->
<!-- |    EDITING THIS FILE BY HAND IS NOT RECOMMENDED                                 | -->
<!-- =================================================================================== -->
<robot name="cheetah">

  <material name="black">
    <color rgba="0.0 0.0 0.0 1.0"/>
  </material>
  <material name="blue">
    <color rgba="0.0 0.0 0.8 1.0"/>
  </material>
  <material name="green">
    <color rgba="0.0 0.8 0.0 1.0"/>
  </material>
  <material name="grey">
    <color rgba="0.2 0.2 0.2 1.0"/>
  </material>
  <material name="silver">
    <color rgba="0.913725490196 0.913725490196 0.847058823529 1.0"/>
  </material>
  <material name="orange">
    <color rgba="1.0 0.423529411765 0.0392156862745 1.0"/>
  </material>
  <material name="brown">
    <color rgba="0.870588235294 0.811764705882 0.764705882353 1.0"/>
  </material>
  <material name="white_gray">
    <color rgba="0.823529411765 0.823529411765 0.823529411765 1.0"/>
  </material>
  <material name="gold">
    <color rgba="0.811764705882 0.678431372549 0.301960784314 1.0"/>
  </material>
  <material name="white_blue">
    <color rgba="0.462745098039 0.8 0.992156862745 1.0"/>
  </material>
  <material name="white_black">
    <color rgba="0.494117647059 0.494117647059 0.494117647059 1.0"/>
  </material>
  <material name="red">
    <color rgba="0.8 0.0 0.0 1.0"/>
  </material>
  <material name="white">
    <color rgba="1.0 1.0 1.0 1.0"/>
  </material>

  <link name="trunk"/>
  <link name="trunk_interia">
    <visual>
      <origin rpy="0 0 0" xyz="0 0 0"/>
      <geometry>
        <mesh filename="../meshes/trunk.STL" scale="1 1 1"/>
      </geometry>
      <material name="white_gray"/>
    </visual>
    <collision>
      <origin rpy="0 0 0" xyz="0 0 0"/>
      <geometry>
        <!-- <mesh filename="../meshes/trunk.STL" scale="1 1 1"/> -->
        <box size="0.3 0.2 0.093"/>
      </geometry>
    </collision>
    <inertial>
      <origin rpy="0 0 0" xyz="0.0 0.0 0.0"/>
      <mass value="3.3"/>
      <inertia ixx="0.011253" ixy="0" ixz="0.0" iyy="0.036203" iyz="-0.0" izz="0.042673"/>
    </inertial>
  </link>
  <joint name="trunk_to_trunk_inertia" type="fixed">
    <origin rpy="0 0 0" xyz="0 0 0"/>
    <parent link="trunk"/>
    <child link="trunk_interia"/>
  </joint>
  <!-- 
    <joint name="imu_joint" type="fixed">
        <parent link="trunk"/>
        <child link="imu_link"/>
        <origin rpy="0 0 0" xyz="0 0 0"/>
    </joint>

    <link name="imu_link">
        <inertial>
            <mass value="0.001"/>
            <origin rpy="0 0 0" xyz="0 0 0"/>
            <inertia ixx="0.0001" ixy="0" ixz="0" iyy="0.000001" iyz="0" izz="0.0001"/>
        </inertial>
        <visual>
            <origin rpy="0 0 0" xyz="0 0 0"/>
            <geometry>
                <box size="0.001 0.001 0.001"/>
            </geometry>
            <material name="red"/>
        </visual>
        <collision>
            <origin rpy="0 0 0" xyz="0 0 0"/>
            <geometry>
                <box size=".001 .001 .001"/>
            </geometry>
        </collision>
    </link> -->
  <!-- //////////////////////hip//////////////////// -->
  <joint name="RL_hip_joint" type="revolute">
    <!-- <joint name="${name}_hip_joint" type="continuous"> -->
    <origin rpy="0 0 0" xyz="-0.196 0.049664 0"/>
    <parent link="trunk"/>
    <child link="RL_hip"/>
    <axis xyz="1 0 0"/>
    <dynamics damping="0" friction="0"/>
    <limit effort="20" lower="-0.872664625997" upper="1.0471975512" velocity="10.6"/>
  </joint>
  <link name="RL_hip">
    <visual>
      <origin rpy="3.14159265359 0 0" xyz="0 0 0"/>
      <geometry>
        <mesh filename="../meshes/hip.STL" scale="1 1 1"/>
      </geometry>
      <material name="gold"/>
    </visual>
    <collision>
      <!-- <origin rpy="${PI/2.0} 0 0" xyz="0 0 0"/> -->
      <!-- <xacro:if value="${(mirror_dae == True) and (front_hind_dae == True)}">
                    <origin rpy="0 0 0" xyz="0 0 0"/>
                </xacro:if>
                <xacro:if value="${(mirror_dae == False) and (front_hind_dae == True)}">
                    <origin rpy="${PI} 0 0" xyz="0 0 0"/>
                </xacro:if>
                <xacro:if value="${(mirror_dae == True) and (front_hind_dae == False)}">
                    <origin rpy="0 ${PI} 0" xyz="0 0 0"/>
                </xacro:if>
                <xacro:if value="${(mirror_dae == False) and (front_hind_dae == False)}">
                    <origin rpy="${PI} ${PI} 0" xyz="0 0 0"/>
                </xacro:if> -->
      <geometry>
        <!-- <mesh filename="../meshes/hip.STL" scale="1 1 1"/> -->
        <box size="0.09 0.08 0.093"/>
      </geometry>
    </collision>
    <inertial>
      <origin rpy="0 0 0" xyz="0.0 -0.036 0.0"/>
      <mass value="0.57"/>
      <inertia ixx="0.0007148275" ixy="0.0" ixz="0.0" iyy="0.0007955775" iyz="0.0" izz="0.00068875"/>
    </inertial>
  </link>
  <!-- //////////////////////thigh//////////////////// -->
  <joint name="RL_thigh_joint" type="revolute">
    <!-- <joint name="${name}_thigh_joint" type="continuous"> -->
    <origin rpy="0 0 0" xyz="0 0.077476 0"/>
    <parent link="RL_hip"/>
    <child link="RL_thigh"/>
    <axis xyz="0 1 0"/>
    <dynamics damping="0" friction="0"/>
    <limit effort="20" lower="-0.523598775598" upper="3.92699081699" velocity="10.6"/>
  </joint>
  <link name="RL_thigh">
    <visual>
      <origin rpy="3.14159265359 3.14159265359 0" xyz="0 0 0"/>
      <geometry>
        <mesh filename="../meshes/thigh.STL" scale="1 1 1"/>
      </geometry>
      <material name="white_blue"/>
    </visual>
    <collision>
      <!-- <xacro:if value="${mirror_dae == True}">
                    <origin rpy="0 0 0" xyz="0 0 0"/>                 
                </xacro:if>
                <xacro:if value="${mirror_dae == False}">
                    <origin rpy="${PI} ${PI} 0" xyz="0 0 0"/>
                </xacro:if> -->
      <origin rpy="0 0 0" xyz="0 0 -0.11"/>
      <geometry>
        <box size="0.043 0.034 0.22"/>
        <!-- <mesh filename="../meshes/thigh.STL" scale="1 1 1"/> -->
      </geometry>
      <material name="white_blue"/>
    </collision>
    <inertial>
      <origin rpy="0 0 0" xyz="0.0 -0.016 -0.11"/>
      <mass value="0.634"/>
      <inertia ixx="0.00261820866667" ixy="0.0" ixz="0.0" iyy="0.00265482216667" iyz="0.0" izz="0.000158764166667"/>
    </inertial>
  </link>
  <!-- //////////////////////calf//////////////////// -->
  <joint name="RL_calf_joint" type="revolute">
    <!-- <joint name="${name}_calf_joint" type="continuous"> -->
    <origin rpy="0 0 0" xyz="0 0 -0.2115"/>
    <parent link="RL_thigh"/>
    <child link="RL_calf"/>
    <axis xyz="0 1 0"/>
    <dynamics damping="0" friction="0"/>
    <!-- <limit effort="${calf_torque_max}" velocity="${calf_velocity_max}" lower="${calf_min*PI/180.0}" upper="${calf_max*PI/180.0}"/> -->
    <limit effort="20" lower="-3.14159265359" upper="3.14159265359" velocity="10.6"/>
  </joint>
  <link name="RL_calf">
    <visual>
      <origin rpy="0 0 0" xyz="0.0 0.009 0.0"/>
      <geometry>
        <mesh filename="../meshes/calf.STL" scale="1 1 1"/>
      </geometry>
      <material name="white_blue"/>
    </visual>
    <collision>
      <origin rpy="0 0 0" xyz="0.0 0.0 -0.1"/>
      <geometry>
        <box size="0.016 0.016 0.2"/>
        <!-- <mesh filename="../meshes/calf.STL" scale="1 1 1"/> -->
      </geometry>
    </collision>
    <inertial>
      <origin rpy="0 0 0" xyz="0.0 0.0 0.0"/>
      <mass value="0.064"/>
      <inertia ixx="0.000214698666667" ixy="0.0" ixz="0.0" iyy="0.000214698666667" iyz="0.0" izz="2.73066666667e-06"/>
    </inertial>
  </link>
  <!-- //////////////////////foot//////////////////// -->
  <joint name="RL_foot_fixed" type="fixed">
    <origin rpy="0 0 0" xyz="0 0 -0.23039"/>
    <parent link="RL_calf"/>
    <child link="RL_foot"/>
  </joint>
  <link name="RL_foot">
    <visual>
      <origin rpy="0 0 0" xyz="0 0.018 0.02"/>
      <geometry>
        <mesh filename="../meshes/foot.STL" scale="1 1 1"/>
      </geometry>
      <material name="white_black"/>
    </visual>
    <collision>
      <origin rpy="0 0 0" xyz="0 0.0 0.025"/>
      <geometry>
        <!-- <mesh filename="../meshes/foot.STL" scale="1 1 1"/> -->
        <sphere radius="0.025"/>
      </geometry>
    </collision>
    <inertial>
      <origin rpy="0 0 0" xyz="0.0 0.0 0"/>
      <mass value="0.15"/>
      <inertia ixx="4.2135e-05" ixy="0.0" ixz="0.0" iyy="4.2135e-05" iyz="0.0" izz="4.2135e-05"/>
    </inertial>
  </link>
  <!-- //////////////////////hip//////////////////// -->
  <joint name="FL_hip_joint" type="revolute">
    <!-- <joint name="${name}_hip_joint" type="continuous"> -->
    <origin rpy="0 0 0" xyz="0.196 0.049664 0"/>
    <parent link="trunk"/>
    <child link="FL_hip"/>
    <axis xyz="1 0 0"/>
    <dynamics damping="0" friction="0"/>
    <limit effort="20" lower="-0.872664625997" upper="1.0471975512" velocity="10.6"/>
  </joint>
  <link name="FL_hip">
    <visual>
      <origin rpy="3.14159265359 3.14159265359 0" xyz="0 0 0"/>
      <geometry>
        <mesh filename="../meshes/hip.STL" scale="1 1 1"/>
      </geometry>
      <material name="gold"/>
    </visual>
    <collision>
      <!-- <origin rpy="${PI/2.0} 0 0" xyz="0 0 0"/> -->
      <!-- <xacro:if value="${(mirror_dae == True) and (front_hind_dae == True)}">
                    <origin rpy="0 0 0" xyz="0 0 0"/>
                </xacro:if>
                <xacro:if value="${(mirror_dae == False) and (front_hind_dae == True)}">
                    <origin rpy="${PI} 0 0" xyz="0 0 0"/>
                </xacro:if>
                <xacro:if value="${(mirror_dae == True) and (front_hind_dae == False)}">
                    <origin rpy="0 ${PI} 0" xyz="0 0 0"/>
                </xacro:if>
                <xacro:if value="${(mirror_dae == False) and (front_hind_dae == False)}">
                    <origin rpy="${PI} ${PI} 0" xyz="0 0 0"/>
                </xacro:if> -->
      <geometry>
        <!-- <mesh filename="../meshes/hip.STL" scale="1 1 1"/> -->
        <box size="0.09 0.08 0.093"/>
      </geometry>
    </collision>
    <inertial>
      <origin rpy="0 0 0" xyz="-0.0 -0.036 0.0"/>
      <mass value="0.57"/>
      <inertia ixx="0.0007148275" ixy="0.0" ixz="0.0" iyy="0.0007955775" iyz="0.0" izz="0.00068875"/>
    </inertial>
  </link>
  <!-- //////////////////////thigh//////////////////// -->
  <joint name="FL_thigh_joint" type="revolute">
    <!-- <joint name="${name}_thigh_joint" type="continuous"> -->
    <origin rpy="0 0 0" xyz="0 0.077476 0"/>
    <parent link="FL_hip"/>
    <child link="FL_thigh"/>
    <axis xyz="0 1 0"/>
    <dynamics damping="0" friction="0"/>
    <limit effort="20" lower="-0.523598775598" upper="3.92699081699" velocity="10.6"/>
  </joint>
  <link name="FL_thigh">
    <visual>
      <origin rpy="3.14159265359 3.14159265359 0" xyz="0 0 0"/>
      <geometry>
        <mesh filename="../meshes/thigh.STL" scale="1 1 1"/>
      </geometry>
      <material name="white_blue"/>
    </visual>
    <collision>
      <!-- <xacro:if value="${mirror_dae == True}">
                    <origin rpy="0 0 0" xyz="0 0 0"/>                 
                </xacro:if>
                <xacro:if value="${mirror_dae == False}">
                    <origin rpy="${PI} ${PI} 0" xyz="0 0 0"/>
                </xacro:if> -->
      <origin rpy="0 0 0" xyz="0 0 -0.11"/>
      <geometry>
        <box size="0.043 0.034 0.22"/>
        <!-- <mesh filename="../meshes/thigh.STL" scale="1 1 1"/> -->
      </geometry>
      <material name="white_blue"/>
    </collision>
    <inertial>
      <origin rpy="0 0 0" xyz="0.0 -0.016 -0.11"/>
      <mass value="0.634"/>
      <inertia ixx="0.00261820866667" ixy="0.0" ixz="0.0" iyy="0.00265482216667" iyz="0.0" izz="0.000158764166667"/>
    </inertial>
  </link>
  <!-- //////////////////////calf//////////////////// -->
  <joint name="FL_calf_joint" type="revolute">
    <!-- <joint name="${name}_calf_joint" type="continuous"> -->
    <origin rpy="0 0 0" xyz="0 0 -0.2115"/>
    <parent link="FL_thigh"/>
    <child link="FL_calf"/>
    <axis xyz="0 1 0"/>
    <dynamics damping="0" friction="0"/>
    <!-- <limit effort="${calf_torque_max}" velocity="${calf_velocity_max}" lower="${calf_min*PI/180.0}" upper="${calf_max*PI/180.0}"/> -->
    <limit effort="20" lower="-3.14159265359" upper="3.14159265359" velocity="10.6"/>
  </joint>
  <link name="FL_calf">
    <visual>
      <origin rpy="0 0 0" xyz="0.0 0.009 0.0"/>
      <geometry>
        <mesh filename="../meshes/calf.STL" scale="1 1 1"/>
      </geometry>
      <material name="white_blue"/>
    </visual>
    <collision>
      <origin rpy="0 0 0" xyz="0.0 0.0 -0.1"/>
      <geometry>
        <box size="0.016 0.016 0.2"/>
        <!-- <mesh filename="../meshes/calf.STL" scale="1 1 1"/> -->
      </geometry>
    </collision>
    <inertial>
      <origin rpy="0 0 0" xyz="0.0 0.0 0.0"/>
      <mass value="0.064"/>
      <inertia ixx="0.000214698666667" ixy="0.0" ixz="0.0" iyy="0.000214698666667" iyz="0.0" izz="2.73066666667e-06"/>
    </inertial>
  </link>
  <!-- //////////////////////foot//////////////////// -->
  <joint name="FL_foot_fixed" type="fixed">
    <origin rpy="0 0 0" xyz="0 0 -0.23039"/>
    <parent link="FL_calf"/>
    <child link="FL_foot"/>
  </joint>
  <link name="FL_foot">
    <visual>
      <origin rpy="0 0 0" xyz="0 0.018 0.02"/>
      <geometry>
        <mesh filename="../meshes/foot.STL" scale="1 1 1"/>
      </geometry>
      <material name="white_black"/>
    </visual>
    <collision>
      <origin rpy="0 0 0" xyz="0 0.0 0.025"/>
      <geometry>
        <!-- <mesh filename="../meshes/foot.STL" scale="1 1 1"/> -->
        <sphere radius="0.025"/>
      </geometry>
    </collision>
    <inertial>
      <origin rpy="0 0 0" xyz="0.0 0.0 0"/>
      <mass value="0.15"/>
      <inertia ixx="4.2135e-05" ixy="0.0" ixz="0.0" iyy="4.2135e-05" iyz="0.0" izz="4.2135e-05"/>
    </inertial>
  </link>

  <!-- //////////////////////hip//////////////////// -->
  <joint name="RR_hip_joint" type="revolute">
    <!-- <joint name="${name}_hip_joint" type="continuous"> -->
    <origin rpy="0 0 0" xyz="-0.196 -0.049664 0"/>
    <parent link="trunk"/>
    <child link="RR_hip"/>
    <axis xyz="1 0 0"/>
    <dynamics damping="0" friction="0"/>
    <limit effort="20" lower="-1.0471975512" upper="0.872664625997" velocity="10.6"/>
  </joint>
  <link name="RR_hip">
    <visual>
      <origin rpy="0 0 0" xyz="0 0 0"/>
      <geometry>
        <mesh filename="../meshes/hip.STL" scale="1 1 1"/>
      </geometry>
      <material name="gold"/>
    </visual>
    <collision>
      <!-- <origin rpy="${PI/2.0} 0 0" xyz="0 0 0"/> -->
      <!-- <xacro:if value="${(mirror_dae == True) and (front_hind_dae == True)}">
                    <origin rpy="0 0 0" xyz="0 0 0"/>
                </xacro:if>
                <xacro:if value="${(mirror_dae == False) and (front_hind_dae == True)}">
                    <origin rpy="${PI} 0 0" xyz="0 0 0"/>
                </xacro:if>
                <xacro:if value="${(mirror_dae == True) and (front_hind_dae == False)}">
                    <origin rpy="0 ${PI} 0" xyz="0 0 0"/>
                </xacro:if>
                <xacro:if value="${(mirror_dae == False) and (front_hind_dae == False)}">
                    <origin rpy="${PI} ${PI} 0" xyz="0 0 0"/>
                </xacro:if> -->
      <geometry>
        <!-- <mesh filename="../meshes/hip.STL" scale="1 1 1"/> -->
        <box size="0.09 0.08 0.093"/>
      </geometry>
    </collision>
    <inertial>
      <origin rpy="0 0 0" xyz="0.0 0.036 0.0"/>
      <mass value="0.57"/>
      <inertia ixx="0.0007148275" ixy="0.0" ixz="0.0" iyy="0.0007955775" iyz="0.0" izz="0.00068875"/>
    </inertial>
  </link>
  <!-- //////////////////////thigh//////////////////// -->
  <joint name="RR_thigh_joint" type="revolute">
    <!-- <joint name="${name}_thigh_joint" type="continuous"> -->
    <origin rpy="0 0 0" xyz="0 -0.077476 0"/>
    <parent link="RR_hip"/>
    <child link="RR_thigh"/>
    <axis xyz="0 1 0"/>
    <dynamics damping="0" friction="0"/>
    <limit effort="20" lower="-0.523598775598" upper="3.92699081699" velocity="10.6"/>
  </joint>
  <link name="RR_thigh">
    <visual>
      <origin rpy="0 0 0" xyz="0 0 0"/>
      <geometry>
        <mesh filename="../meshes/thigh.STL" scale="1 1 1"/>
      </geometry>
      <material name="white_blue"/>
    </visual>
    <collision>
      <!-- <xacro:if value="${mirror_dae == True}">
                    <origin rpy="0 0 0" xyz="0 0 0"/>                 
                </xacro:if>
                <xacro:if value="${mirror_dae == False}">
                    <origin rpy="${PI} ${PI} 0" xyz="0 0 0"/>
                </xacro:if> -->
      <origin rpy="0 0 0" xyz="0 0 -0.11"/>
      <geometry>
        <box size="0.043 0.034 0.22"/>
        <!-- <mesh filename="../meshes/thigh.STL" scale="1 1 1"/> -->
      </geometry>
      <material name="white_blue"/>
    </collision>
    <inertial>
      <origin rpy="0 0 0" xyz="0.0 0.016 -0.11"/>
      <mass value="0.634"/>
      <inertia ixx="0.00261820866667" ixy="0.0" ixz="0.0" iyy="0.00265482216667" iyz="0.0" izz="0.000158764166667"/>
    </inertial>
  </link>
  <!-- //////////////////////calf//////////////////// -->
  <joint name="RR_calf_joint" type="revolute">
    <!-- <joint name="${name}_calf_joint" type="continuous"> -->
    <origin rpy="0 0 0" xyz="0 0 -0.2115"/>
    <parent link="RR_thigh"/>
    <child link="RR_calf"/>
    <axis xyz="0 1 0"/>
    <dynamics damping="0" friction="0"/>
    <!-- <limit effort="${calf_torque_max}" velocity="${calf_velocity_max}" lower="${calf_min*PI/180.0}" upper="${calf_max*PI/180.0}"/> -->
    <limit effort="20" lower="-3.14159265359" upper="3.14159265359" velocity="10.6"/>
  </joint>
  <link name="RR_calf">
    <visual>
      <origin rpy="0 0 0" xyz="0.0 0.009 0.0"/>
      <geometry>
        <mesh filename="../meshes/calf.STL" scale="1 1 1"/>
      </geometry>
      <material name="white_blue"/>
    </visual>
    <collision>
      <origin rpy="0 0 0" xyz="0.0 0.0 -0.1"/>
      <geometry>
        <box size="0.016 0.016 0.2"/>
        <!-- <mesh filename="../meshes/calf.STL" scale="1 1 1"/> -->
      </geometry>
    </collision>
    <inertial>
      <origin rpy="0 0 0" xyz="0.0 0.0 0.0"/>
      <mass value="0.064"/>
      <inertia ixx="0.000214698666667" ixy="0.0" ixz="0.0" iyy="0.000214698666667" iyz="0.0" izz="2.73066666667e-06"/>
    </inertial>
  </link>
  <!-- //////////////////////foot//////////////////// -->
  <joint name="RR_foot_fixed" type="fixed">
    <origin rpy="0 0 0" xyz="0 0 -0.23039"/>
    <parent link="RR_calf"/>
    <child link="RR_foot"/>
  </joint>
  <link name="RR_foot">
    <visual>
      <origin rpy="0 0 0" xyz="0 0.018 0.02"/>
      <geometry>
        <mesh filename="../meshes/foot.STL" scale="1 1 1"/>
      </geometry>
      <material name="white_black"/>
    </visual>
    <collision>
      <origin rpy="0 0 0" xyz="0 0.0 0.025"/>
      <geometry>
        <!-- <mesh filename="../meshes/foot.STL" scale="1 1 1"/> -->
        <sphere radius="0.025"/>
      </geometry>
    </collision>
    <inertial>
      <origin rpy="0 0 0" xyz="0.0 0.0 0"/>
      <mass value="0.15"/>
      <inertia ixx="4.2135e-05" ixy="0.0" ixz="0.0" iyy="4.2135e-05" iyz="0.0" izz="4.2135e-05"/>
    </inertial>
  </link>

  <!-- //////////////////////hip//////////////////// -->
  <joint name="FR_hip_joint" type="revolute">
    <!-- <joint name="${name}_hip_joint" type="continuous"> -->
    <origin rpy="0 0 0" xyz="0.196 -0.049664 0"/>
    <parent link="trunk"/>
    <child link="FR_hip"/>
    <axis xyz="1 0 0"/>
    <dynamics damping="0" friction="0"/>
    <limit effort="20" lower="-1.0471975512" upper="0.872664625997" velocity="10.6"/>
  </joint>
  <link name="FR_hip">
    <visual>
      <origin rpy="0 3.14159265359 0" xyz="0 0 0"/>
      <geometry>
        <mesh filename="../meshes/hip.STL" scale="1 1 1"/>
      </geometry>
      <material name="gold"/>
    </visual>
    <collision>

      <geometry>
        <!-- <mesh filename="../meshes/hip.STL" scale="1 1 1"/> -->
        <box size="0.09 0.08 0.093"/>
      </geometry>
    </collision>
    <inertial>
      <origin rpy="0 0 0" xyz="-0.0 0.036 0.0"/>
      <mass value="0.57"/>
      <inertia ixx="0.0007148275" ixy="0.0" ixz="0.0" iyy="0.0007955775" iyz="0.0" izz="0.00068875"/>
    </inertial>
  </link>
  <!-- //////////////////////thigh//////////////////// -->
  <joint name="FR_thigh_joint" type="revolute">
    <!-- <joint name="${name}_thigh_joint" type="continuous"> -->
    <origin rpy="0 0 0" xyz="0 -0.077476 0"/>
    <parent link="FR_hip"/>
    <child link="FR_thigh"/>
    <axis xyz="0 1 0"/>
    <dynamics damping="0" friction="0"/>
    <limit effort="20" lower="-0.523598775598" upper="3.92699081699" velocity="10.6"/>
  </joint>
  <link name="FR_thigh">
    <visual>
      <origin rpy="0 0 0" xyz="0 0 0"/>
      <geometry>
        <mesh filename="../meshes/thigh.STL" scale="1 1 1"/>
      </geometry>
      <material name="white_blue"/>
    </visual>
    <collision>
      <!-- <xacro:if value="${mirror_dae == True}">
                    <origin rpy="0 0 0" xyz="0 0 0"/>                 
                </xacro:if>
                <xacro:if value="${mirror_dae == False}">
                    <origin rpy="${PI} ${PI} 0" xyz="0 0 0"/>
                </xacro:if> -->
      <origin rpy="0 0 0" xyz="0 0 -0.11"/>
      <geometry>
        <box size="0.043 0.034 0.22"/>
        <!-- <mesh filename="../meshes/thigh.STL" scale="1 1 1"/> -->
      </geometry>
      <material name="white_blue"/>
    </collision>
    <inertial>
      <origin rpy="0 0 0" xyz="0.0 0.016 -0.11"/>
      <mass value="0.634"/>
      <inertia ixx="0.00261820866667" ixy="0.0" ixz="0.0" iyy="0.00265482216667" iyz="0.0" izz="0.000158764166667"/>
    </inertial>
  </link>
  <!-- //////////////////////calf//////////////////// -->
  <joint name="FR_calf_joint" type="revolute">
    <!-- <joint name="${name}_calf_joint" type="continuous"> -->
    <origin rpy="0 0 0" xyz="0 0 -0.2115"/>
    <parent link="FR_thigh"/>
    <child link="FR_calf"/>
    <axis xyz="0 1 0"/>
    <dynamics damping="0" friction="0"/>
    <!-- <limit effort="${calf_torque_max}" velocity="${calf_velocity_max}" lower="${calf_min*PI/180.0}" upper="${calf_max*PI/180.0}"/> -->
    <limit effort="20" lower="-3.14159265359" upper="3.14159265359" velocity="10.6"/>
  </joint>
  <link name="FR_calf">
    <visual>
      <origin rpy="0 0 0" xyz="0.0 0.009 0.0"/>
      <geometry>
        <mesh filename="../meshes/calf.STL" scale="1 1 1"/>
      </geometry>
      <material name="white_blue"/>
    </visual>
    <collision>
      <origin rpy="0 0 0" xyz="0.0 0.0 -0.1"/>
      <geometry>
        <box size="0.016 0.016 0.2"/>
        <!-- <mesh filename="../meshes/calf.STL" scale="1 1 1"/> -->
      </geometry>
    </collision>
    <inertial>
      <origin rpy="0 0 0" xyz="0.0 0.0 0.0"/>
      <mass value="0.064"/>
      <inertia ixx="0.000214698666667" ixy="0.0" ixz="0.0" iyy="0.000214698666667" iyz="0.0" izz="2.73066666667e-06"/>
    </inertial>
  </link>
  <!-- //////////////////////foot//////////////////// -->
  <joint name="FR_foot_fixed" type="fixed">
    <origin rpy="0 0 0" xyz="0 0 -0.23039"/>
    <parent link="FR_calf"/>
    <child link="FR_foot"/>
  </joint>
  <link name="FR_foot">
    <visual>
      <origin rpy="0 0 0" xyz="0 0.018 0.02"/>
      <geometry>
        <mesh filename="../meshes/foot.STL" scale="1 1 1"/>
      </geometry>
      <material name="white_black"/>
    </visual>
    <collision>
      <origin rpy="0 0 0" xyz="0 0.0 0.025"/>
      <geometry>
        <!-- <mesh filename="../meshes/foot.STL" scale="1 1 1"/> -->
        <sphere radius="0.025"/>
      </geometry>
    </collision>
    <inertial>
      <origin rpy="0 0 0" xyz="0.0 0.0 0"/>
      <mass value="0.15"/>
      <inertia ixx="4.2135e-05" ixy="0.0" ixz="0.0" iyy="4.2135e-05" iyz="0.0" izz="4.2135e-05"/>
    </inertial>
  </link>

  <joint name="hokuyo_joint" type="fixed">
    <origin rpy="0 0 0" xyz="0.0 0.0 0.093"/>
    <parent link="trunk"/>
    <child link="hokuyo_frame"/>
  </joint>
  <link name="hokuyo_frame">
    <inertial>
      <mass value="0.270"/>
      <origin rpy="0 0 0" xyz="0 0 0"/>
      <inertia ixx="2.632e-4" ixy="0" ixz="0" iyy="2.632e-4" iyz="0" izz="1.62e-4"/>
    </inertial>
    <visual>
      <origin rpy="0 0 0" xyz="0 0 0"/>
      <geometry>
        <mesh filename="package://hector_sensors_description/meshes/hokuyo_utm30lx/hokuyo_utm_30lx.dae"/>
      </geometry>
    </visual>
    <collision>
      <origin rpy="0 0 0" xyz="0 0 -0.0115"/>
      <geometry>
        <box size="0.058 0.058 0.087"/>
        <!--<mesh filename="package://hector_sensors_description/meshes/hokuyo_utm30lx/hokuyo_utm_30lx.stl"/>-->
      </geometry>
    </collision>
  </link>


  <joint name="camera_joint" type="fixed">
    <origin rpy="0 0.261799612195482 0" xyz="0.1 0.0 -0.06"/>
    <parent link="trunk"/>
    <child link="camera_link"/>
  </joint>
  <link name="camera_link">
    <inertial>
      <mass value="0.200"/>
      <origin rpy="0 0 0" xyz="0 0 0"/>
      <inertia ixx="5.8083e-4" ixy="0" ixz="0" iyy="3.0833e-5" iyz="0" izz="5.9083e-4"/>
    </inertial>
    <visual>
      <origin rpy="0 0 0" xyz="0 0 0"/>
      <geometry>
        <mesh filename="package://hector_sensors_description/meshes/asus_camera/asus_camera_simple.dae"/>
      </geometry>
    </visual>
    <!--        
       <collision>
          <origin xyz="0 0 0" rpy="0 0 0" />
          <geometry>
            <box size="0.035 0.185 0.025"/>
          </geometry>
        </collision>
        -->
    <collision>
      <origin rpy="0 0 0" xyz="0 0 0"/>
      <geometry>
        <mesh filename="package://hector_sensors_description/meshes/asus_camera/asus_camera_simple.dae"/>
      </geometry>
    </collision>
  </link>
  <joint name="camera_depth_joint" type="fixed">
    <origin rpy="0 0 0" xyz="0.0 0.049 0.0"/>
    <parent link="camera_link"/>
    <child link="camera_depth_frame"/>
  </joint>
  <link name="camera_depth_frame"/>
  <joint name="camera_depth_optical_joint" type="fixed">
    <origin rpy="-1.57079632679 0.0 -1.57079632679" xyz="0 0 0"/>
    <parent link="camera_depth_frame"/>
    <child link="camera_depth_optical_frame"/>
  </joint>
  <link name="camera_depth_optical_frame"/>
  <joint name="camera_rgb_joint" type="fixed">
    <origin rpy="0 0 0" xyz="0.0 0.022 0.0"/>
    <parent link="camera_link"/>
    <child link="camera_rgb_frame"/>
  </joint>
  <link name="camera_rgb_frame"/>
  <joint name="camera_rgb_optical_joint" type="fixed">
    <origin rpy="-1.57079632679 0.0 -1.57079632679" xyz="0 0 0"/>
    <parent link="camera_rgb_frame"/>
    <child link="camera_rgb_optical_frame"/>
  </joint>
  <link name="camera_rgb_optical_frame"/>
  <!-- ASUS Xtion PRO camera for simulation -->

  <link name="imu_link">
    <inertial>
      <mass value="0.001"/>
      <origin rpy="0 0 0" xyz="0 0 0"/>
      <inertia ixx="1e-09" ixy="0.0" ixz="0.0" iyy="1e-09" iyz="0.0" izz="1e-09"/>
    </inertial>
  </link>
  <joint name="imu_joint" type="fixed">
    <parent link="trunk"/>
    <child link="imu_link"/>
  </joint>

</robot>

